<?xml version="1.0" ?>
<sdf version="1.7">
  <model name="simple_robot">
    <!-- Base link -->
    <link name="chassis">
      <pose>0 0 0.15 0 0 0</pose>
      <inertial>
        <mass>5.0</mass>
        <inertia>
          <ixx>0.1</ixx>
          <ixy>0</ixy>
          <ixz>0</ixz>
          <iyy>0.1</iyy>
          <iyz>0</iyz>
          <izz>0.2</izz>
        </inertia>
      </inertial>

      <collision name="collision">
        <geometry>
          <box>
            <size>0.5 0.3 0.3</size>
          </box>
        </geometry>
      </collision>

      <visual name="visual">
        <geometry>
          <box>
            <size>0.5 0.3 0.3</size>
          </box>
        </geometry>
        <material>
          <ambient>0.2 0.6 1.0 1</ambient>
          <diffuse>0.2 0.6 1.0 1</diffuse>
        </material>
      </visual>
    </link>

    <!-- Left wheel -->
    <link name="left_wheel">
      <inertial>
        <mass>0.5</mass>
        <inertia>
          <ixx>0.001</ixx>
          <ixy>0</ixy>
          <ixz>0</ixz>
          <iyy>0.001</iyy>
          <iyz>0</iyz>
          <izz>0.002</izz>
        </inertia>
      </inertial>

      <collision name="collision">
        <geometry>
          <cylinder>
            <radius>0.1</radius>
            <length>0.05</length>
          </cylinder>
        </geometry>
      </collision>

      <visual name="visual">
        <geometry>
          <cylinder>
            <radius>0.1</radius>
            <length>0.05</length>
          </cylinder>
        </geometry>
        <material>
          <ambient>0.2 0.2 0.2 1</ambient>
          <diffuse>0.2 0.2 0.2 1</diffuse>
        </material>
      </visual>
    </link>

    <!-- Right wheel -->
    <link name="right_wheel">
      <inertial>
        <mass>0.5</mass>
        <inertia>
          <ixx>0.001</ixx>
          <ixy>0</ixy>
          <ixz>0</ixz>
          <iyy>0.001</iyy>
          <iyz>0</iyz>
          <izz>0.002</izz>
        </inertia>
      </inertial>

      <collision name="collision">
        <geometry>
          <cylinder>
            <radius>0.1</radius>
            <length>0.05</length>
          </cylinder>
        </geometry>
      </collision>

      <visual name="visual">
        <geometry>
          <cylinder>
            <radius>0.1</radius>
            <length>0.05</length>
          </cylinder>
        </geometry>
        <material>
          <ambient>0.2 0.2 0.2 1</ambient>
          <diffuse>0.2 0.2 0.2 1</diffuse>
        </material>
      </visual>
    </link>

    <!-- Caster wheel -->
    <link name="caster_wheel">
      <inertial>
        <mass>0.1</mass>
        <inertia>
          <ixx>0.0001</ixx>
          <ixy>0</ixy>
          <ixz>0</ixz>
          <iyy>0.0001</iyy>
          <iyz>0</iyz>
          <izz>0.0001</izz>
        </inertia>
      </inertial>

      <collision name="collision">
        <geometry>
          <sphere>
            <radius>0.05</radius>
          </sphere>
        </geometry>
      </collision>

      <visual name="visual">
        <geometry>
          <sphere>
            <radius>0.05</radius>
          </sphere>
        </geometry>
        <material>
          <ambient>0.5 0.5 0.5 1</ambient>
          <diffuse>0.5 0.5 0.5 1</diffuse>
        </material>
      </visual>
    </link>

    <!-- Camera -->
    <link name="camera">
      <inertial>
        <mass>0.01</mass>
        <inertia>
          <ixx>0.0001</ixx>
          <ixy>0</ixy>
          <ixz>0</ixz>
          <iyy>0.0001</iyy>
          <iyz>0</iyz>
          <izz>0.0001</izz>
        </inertia>
      </inertial>

      <visual name="visual">
        <geometry>
          <box>
            <size>0.05 0.05 0.03</size>
          </box>
        </geometry>
        <material>
          <ambient>0.1 0.1 0.1 1</ambient>
          <diffuse>0.1 0.1 0.1 1</diffuse>
        </material>
      </visual>
    </link>

    <!-- Joints -->
    <joint name="left_wheel_joint" type="revolute">
      <parent>chassis</parent>
      <child>left_wheel</child>
      <pose>0.15 0.2 -0.1 0 0 0</pose>
      <axis>
        <xyz>0 1 0</xyz>
        <limit>
          <effort>100</effort>
          <velocity>100</velocity>
        </limit>
      </axis>
    </joint>

    <joint name="right_wheel_joint" type="revolute">
      <parent>chassis</parent>
      <child>right_wheel</child>
      <pose>0.15 -0.2 -0.1 0 0 0</pose>
      <axis>
        <xyz>0 1 0</xyz>
        <limit>
          <effort>100</effort>
          <velocity>100</velocity>
        </limit>
      </axis>
    </joint>

    <joint name="caster_joint" type="fixed">
      <parent>chassis</parent>
      <child>caster_wheel</child>
      <pose>-0.2 0.0 -0.05 0 0 0</pose>
    </joint>

    <joint name="camera_joint" type="fixed">
      <parent>chassis</parent>
      <child>camera</child>
      <pose>0.2 0.0 0.1 0 0 0</pose>
    </joint>

    <!-- Gazebo plugins -->
    <gazebo reference="chassis">
      <material>Gazebo/Blue</material>
    </gazebo>

    <gazebo reference="left_wheel">
      <material>Gazebo/Black</material>
    </gazebo>

    <gazebo reference="right_wheel">
      <material>Gazebo/Black</material>
    </gazebo>

    <gazebo reference="caster_wheel">
      <material>Gazebo/Grey</material>
    </gazebo>

    <gazebo reference="camera">
      <material>Gazebo/Black</material>
    </gazebo>

    <!-- Differential drive plugin -->
    <gazebo>
      <plugin name="diff_drive" filename="libgazebo_ros_diff_drive.so">
        <left_joint>left_wheel_joint</left_joint>
        <right_joint>right_wheel_joint</right_joint>
        <wheel_separation>0.4</wheel_separation>
        <wheel_diameter>0.2</wheel_diameter>
        <max_wheel_torque>20</max_wheel_torque>
        <max_wheel_acceleration>1.0</max_wheel_acceleration>
        <command_topic>cmd_vel</command_topic>
        <odometry_topic>odom</odometry_topic>
        <odometry_frame>odom</odometry_frame>
        <robot_base_frame>chassis</robot_base_frame>
        <publish_odom>true</publish_odom>
        <publish_odom_tf>true</publish_odom_tf>
        <publish_wheel_tf>true</publish_wheel_tf>
      </plugin>
    </gazebo>

    <!-- Camera sensor plugin -->
    <gazebo reference="camera">
      <sensor type="camera" name="camera">
        <update_rate>30.0</update_rate>
        <camera name="head">
          <horizontal_fov>1.047</horizontal_fov>
          <image>
            <width>640</width>
            <height>480</height>
            <format>R8G8B8</format>
          </image>
          <clip>
            <near>0.02</near>
            <far>300</far>
          </clip>
        </camera>
        <plugin name="camera_controller" filename="libgazebo_ros_camera.so">
          <alwaysOn>true</alwaysOn>
          <updateRate>0.0</updateRate>
          <cameraName>simple_camera</cameraName>
          <imageTopicName>image_raw</imageTopicName>
          <cameraInfoTopicName>camera_info</cameraInfoTopicName>
          <frameName>camera</frameName>
        </plugin>
      </sensor>
    </gazebo>
  </model>
</sdf>